2023-07-29 23:45:41,535 INFO    StreamThr :9100 [internal.py:wandb_internal():86] W&B internal server running at pid: 9100, started at: 2023-07-29 23:45:41.534186
2023-07-29 23:45:41,537 DEBUG   HandlerThread:9100 [handler.py:handle_request():144] handle_request: status
2023-07-29 23:45:41,548 INFO    WriterThread:9100 [datastore.py:open_for_write():85] open: C:\Users\dhpng\summer_projects\Mario_RL\wandb\run-20230729_234541-deapsc6s\run-deapsc6s.wandb
2023-07-29 23:45:41,550 DEBUG   SenderThread:9100 [sender.py:send():369] send: header
2023-07-29 23:45:41,602 DEBUG   SenderThread:9100 [sender.py:send():369] send: run
2023-07-29 23:45:42,106 ERROR   SenderThread:9100 [internal_api.py:execute():323] 404 response executing GraphQL.
2023-07-29 23:45:42,106 ERROR   SenderThread:9100 [internal_api.py:execute():324] {"errors":[{"message":"entity mario_rl not found during upsertBucket","path":["upsertBucket"]}],"data":{"upsertBucket":null}}
2023-07-29 23:45:42,112 ERROR   SenderThread:9100 [sender.py:send_run():955] It appears that you do not have permission to access the requested resource. Please reach out to the project owner to grant you access. If you have the correct permissions, verify that there are no issues with your networking setup.(Error 404: Not Found)
Traceback (most recent call last):
  File "C:\Users\dhpng\anaconda3\envs\mario_gpu\Lib\site-packages\wandb\sdk\lib\retry.py", line 131, in __call__
    result = self._call_fn(*args, **kwargs)
             ^^^^^^^^^^^^^^^^^^^^^^^^^^^^^^
  File "C:\Users\dhpng\anaconda3\envs\mario_gpu\Lib\site-packages\wandb\sdk\internal\internal_api.py", line 320, in execute
    return self.client.execute(*args, **kwargs)  # type: ignore
           ^^^^^^^^^^^^^^^^^^^^^^^^^^^^^^^^^^^^
  File "C:\Users\dhpng\anaconda3\envs\mario_gpu\Lib\site-packages\wandb\vendor\gql-0.2.0\wandb_gql\client.py", line 52, in execute
    result = self._get_result(document, *args, **kwargs)
             ^^^^^^^^^^^^^^^^^^^^^^^^^^^^^^^^^^^^^^^^^^^
  File "C:\Users\dhpng\anaconda3\envs\mario_gpu\Lib\site-packages\wandb\vendor\gql-0.2.0\wandb_gql\client.py", line 60, in _get_result
    return self.transport.execute(document, *args, **kwargs)
           ^^^^^^^^^^^^^^^^^^^^^^^^^^^^^^^^^^^^^^^^^^^^^^^^^
  File "C:\Users\dhpng\anaconda3\envs\mario_gpu\Lib\site-packages\wandb\sdk\lib\gql_request.py", line 56, in execute
    request.raise_for_status()
  File "C:\Users\dhpng\anaconda3\envs\mario_gpu\Lib\site-packages\requests\models.py", line 1021, in raise_for_status
    raise HTTPError(http_error_msg, response=self)
requests.exceptions.HTTPError: 404 Client Error: Not Found for url: https://api.wandb.ai/graphql

During handling of the above exception, another exception occurred:

Traceback (most recent call last):
  File "C:\Users\dhpng\anaconda3\envs\mario_gpu\Lib\site-packages\wandb\sdk\internal\sender.py", line 953, in send_run
    self._init_run(run, config_value_dict)
  File "C:\Users\dhpng\anaconda3\envs\mario_gpu\Lib\site-packages\wandb\sdk\internal\sender.py", line 991, in _init_run
    server_run, inserted, server_messages = self._api.upsert_run(
                                            ^^^^^^^^^^^^^^^^^^^^^
  File "C:\Users\dhpng\anaconda3\envs\mario_gpu\Lib\site-packages\wandb\apis\normalize.py", line 73, in wrapper
    raise err
  File "C:\Users\dhpng\anaconda3\envs\mario_gpu\Lib\site-packages\wandb\apis\normalize.py", line 41, in wrapper
    return func(*args, **kwargs)
           ^^^^^^^^^^^^^^^^^^^^^
  File "C:\Users\dhpng\anaconda3\envs\mario_gpu\Lib\site-packages\wandb\sdk\internal\internal_api.py", line 1727, in upsert_run
    response = self.gql(
               ^^^^^^^^^
  File "C:\Users\dhpng\anaconda3\envs\mario_gpu\Lib\site-packages\wandb\sdk\internal\internal_api.py", line 292, in gql
    ret = self._retry_gql(
          ^^^^^^^^^^^^^^^^
  File "C:\Users\dhpng\anaconda3\envs\mario_gpu\Lib\site-packages\wandb\sdk\lib\retry.py", line 147, in __call__
    retry_timedelta_triggered = check_retry_fn(e)
                                ^^^^^^^^^^^^^^^^^
  File "C:\Users\dhpng\anaconda3\envs\mario_gpu\Lib\site-packages\wandb\util.py", line 908, in check_retry_fn
    return fallback_retry_fn(e)
           ^^^^^^^^^^^^^^^^^^^^
  File "C:\Users\dhpng\anaconda3\envs\mario_gpu\Lib\site-packages\wandb\util.py", line 850, in no_retry_auth
    raise CommError(
wandb.errors.CommError: It appears that you do not have permission to access the requested resource. Please reach out to the project owner to grant you access. If you have the correct permissions, verify that there are no issues with your networking setup.(Error 404: Not Found)
2023-07-29 23:45:42,971 DEBUG   HandlerThread:9100 [handler.py:handle_request():144] handle_request: shutdown
2023-07-29 23:45:42,971 INFO    HandlerThread:9100 [handler.py:finish():854] shutting down handler
2023-07-29 23:45:43,139 INFO    SenderThread:9100 [sender.py:finish():1526] shutting down sender
2023-07-29 23:45:43,622 INFO    WriterThread:9100 [datastore.py:close():298] close: C:\Users\dhpng\summer_projects\Mario_RL\wandb\run-20230729_234541-deapsc6s\run-deapsc6s.wandb
